iepExampleData.json
/* 1 */
[
    {
        "_id" : ObjectId("5ead7a205249898b3309215a"),
        "orderId" : "_68q9k0s57",
        "action" : "BID",
        "type" : "LIMIT",
        "qty" : 2000,
        "price" : 31.8,
        "status" : "OPEN",
        "createAt" : ISODate("2020-05-02T13:48:16.991Z"),
        "__v" : 0
    },
    {
        "_id" : ObjectId("5ead7a285249898b3309215d"),
        "orderId" : "_p11112f4w",
        "action" : "BID",
        "type" : "LIMIT",
        "qty" : 6000,
        "price" : 31.9,
        "status" : "OPEN",
        "createAt" : ISODate("2020-05-02T13:48:24.685Z"),
        "__v" : 0
    },
    {
        "_id" : ObjectId("5ead7a2c5249898b33092160"),
        "orderId" : "_qer5aotoh",
        "action" : "BID",
        "type" : "LIMIT",
        "qty" : 3000,
        "price" : 31.9,
        "status" : "OPEN",
        "createAt" : ISODate("2020-05-02T13:48:28.448Z"),
        "__v" : 0
    },
    {
        "_id" : ObjectId("5ead7a325249898b33092163"),
        "orderId" : "_5x2a5tkid",
        "action" : "BID",
        "type" : "LIMIT",
        "qty" : 2000,
        "price" : 31.9,
        "status" : "OPEN",
        "createAt" : ISODate("2020-05-02T13:48:34.120Z"),
        "__v" : 0
    },
    {
        "_id" : ObjectId("5ead7a3c5249898b33092166"),
        "orderId" : "_6cby29hne",
        "action" : "BID",
        "type" : "LIMIT",
        "qty" : 1000,
        "price" : 32,
        "status" : "OPEN",
        "createAt" : ISODate("2020-05-02T13:48:44.455Z"),
        "__v" : 0
    },
    {
        "_id" : ObjectId("5ead7a405249898b33092169"),
        "orderId" : "_16vctz2iy",
        "action" : "BID",
        "type" : "LIMIT",
        "qty" : 8000,
        "price" : 32,
        "status" : "OPEN",
        "createAt" : ISODate("2020-05-02T13:48:48.562Z"),
        "__v" : 0
    },
    {
        "_id" : ObjectId("5ead7a4d5249898b3309216c"),
        "orderId" : "_82nh5dzdi",
        "action" : "BID",
        "type" : "MARKET",
        "qty" : 2000,
        "price" : 9007199254740991.0,
        "status" : "OPEN",
        "createAt" : ISODate("2020-05-02T13:49:01.427Z"),
        "__v" : 0
    },
    {
        "_id" : ObjectId("5ead7a735249898b3309216f"),
        "orderId" : "_ky20m18b5",
        "action" : "ASK",
        "type" : "LIMIT",
        "qty" : 4000,
        "price" : 32.2,
        "status" : "OPEN",
        "createAt" : ISODate("2020-05-02T13:49:39.211Z"),
        "__v" : 0
    },
    {
        "_id" : ObjectId("5ead7a785249898b33092172"),
        "orderId" : "_8mr9k0xo5",
        "action" : "ASK",
        "type" : "LIMIT",
        "qty" : 2000,
        "price" : 32.2,
        "status" : "OPEN",
        "createAt" : ISODate("2020-05-02T13:49:44.510Z"),
        "__v" : 0
    },
    {
        "_id" : ObjectId("5ead7a7f5249898b33092175"),
        "orderId" : "_2bghrfaq4",
        "action" : "ASK",
        "type" : "LIMIT",
        "qty" : 1000,
        "price" : 32.2,
        "status" : "OPEN",
        "createAt" : ISODate("2020-05-02T13:49:51.206Z"),
        "__v" : 0
    },
    {
        "_id" : ObjectId("5ead7a865249898b33092178"),
        "orderId" : "_8wkj6a1kk",
        "action" : "ASK",
        "type" : "LIMIT",
        "qty" : 6000,
        "price" : 32.1,
        "status" : "OPEN",
        "createAt" : ISODate("2020-05-02T13:49:58.845Z"),
        "__v" : 0
    },
    {
        "_id" : ObjectId("5ead7a8b5249898b3309217b"),
        "orderId" : "_hhcbwzt3o",
        "action" : "ASK",
        "type" : "LIMIT",
        "qty" : 2000,
        "price" : 32.1,
        "status" : "OPEN",
        "createAt" : ISODate("2020-05-02T13:50:03.143Z"),
        "__v" : 0
    },
    {
        "_id" : ObjectId("5ead7a925249898b3309217e"),
        "orderId" : "_0a4tw4zpo",
        "action" : "ASK",
        "type" : "LIMIT",
        "qty" : 10000,
        "price" : 32,
        "status" : "OPEN",
        "createAt" : ISODate("2020-05-02T13:50:10.541Z"),
        "__v" : 0
    },
    {
        "_id" : ObjectId("5ead7a975249898b33092181"),
        "orderId" : "_4u50xgbir",
        "action" : "ASK",
        "type" : "LIMIT",
        "qty" : 4000,
        "price" : 32,
        "status" : "OPEN",
        "createAt" : ISODate("2020-05-02T13:50:15.505Z"),
        "__v" : 0
    },
    {
        "_id" : ObjectId("5ead7a9b5249898b33092184"),
        "orderId" : "_hq6eevrsz",
        "action" : "ASK",
        "type" : "LIMIT",
        "qty" : 2000,
        "price" : 32,
        "status" : "OPEN",
        "createAt" : ISODate("2020-05-02T13:50:19.984Z"),
        "__v" : 0
    },
    {
        "_id" : ObjectId("5ead7aa55249898b33092187"),
        "orderId" : "_ufgrg641y",
        "action" : "ASK",
        "type" : "LIMIT",
        "qty" : 2000,
        "price" : 31.9,
        "status" : "OPEN",
        "createAt" : ISODate("2020-05-02T13:50:29.143Z"),
        "__v" : 0
    },
    {
        "_id" : ObjectId("5ead7aa85249898b3309218a"),
        "orderId" : "_rxplx5ohn",
        "action" : "ASK",
        "type" : "LIMIT",
        "qty" : 8000,
        "price" : 31.9,
        "status" : "OPEN",
        "createAt" : ISODate("2020-05-02T13:50:32.525Z"),
        "__v" : 0
    }
]
